Workbook

Sheet Untransformed
A1: s0-9i | B1: s10-19i | C1: s20-29i | D1: s30-39i | E1: s40-49i | F1: s50-59i | G1: s60-69i | H1: s70-79i | I1: v0-9i | J1: v10-19i | K1: v20-29i | L1: v30-39i | M1: v40-49i | N1: v50-59i | O1: v60-69i | P1: v70-79i | Q1: s0-9 | R1: s10-19 | S1: s20-29 | T1: s30-39 | U1: s40-49 | V1: s50-59 | W1: s60-69 | X1: s70-79 | Y1: v0-9 | Z1: v10-19 | AA1: v20-29 | AB1: v30-39 | AC1: v40-49 | AD1: v50-59 | AE1: v60-69 | AF1: v70-79 | AG1: kl_div
A2: 1.2883195 | B2: 1.5881146 | C2: 1 | D2: 0.30462764 | E2: 0.65418833 | F2: 0.81571258 | G2: 1.3178923 | H2: 1.112446 | I2: 0.32334112 | J2: 0.68525252 | K2: 1 | L2: 0.72026097 | M2: 1.2793036 | N2: 0.84149434 | O2: 1.1399313 | P2: 2.1282672 | Q2: 0.18155573 | R2: 0.29926359 | S2: 1 | T2: 1.2756143 | U2: 1.8103123 | V2: 2.2368284 | W2: 2.4576894 | X2: 2.3887079 | Y2: 5.1358513 | Z2: 1.6176066 | AA2: 1 | AB2: 1.269717 | AC2: 0.1043196 | AD2: 1.0167224 | AE2: 1.371546 | AF2: 3.0871243 | AG2: 10802.343
A3: 1.2883195 | B3: 1.5881146 | C3: 1 | D3: 0.30462764 | E3: 0.65418833 | F3: 0.81571258 | G3: 1.3178923 | H3: 1.112446 | I3: 0.32334112 | J3: 0.68525252 | K3: 1 | L3: 0.72026097 | M3: 1.2793036 | N3: 0.84149434 | O3: 1.1399313 | P3: 2.1282672 | Q3: 0.18424668 | R3: 0.30396817 | S3: 1 | T3: 1.2843383 | U3: 1.8314098 | V3: 2.2554082 | W3: 2.4878405 | X3: 2.4257613 | Y3: 4.9073791 | Z3: 1.5396554 | AA3: 1 | AB3: 1.2457713 | AC3: 0.084215451 | AD3: 0.99443608 | AE3: 1.3161904 | AF3: 2.9761525 | AG3: 10803.053
A4: 1.2883195 | B4: 1.5881146 | C4: 1 | D4: 0.30462764 | E4: 0.65418833 | F4: 0.81571258 | G4: 1.3178923 | H4: 1.112446 | I4: 0.32334112 | J4: 0.68525252 | K4: 1 | L4: 0.72026097 | M4: 1.2793036 | N4: 0.84149434 | O4: 1.1399313 | P4: 2.1282672 | Q4: 0.18775563 | R4: 0.34674327 | S4: 1 | T4: 1.3147554 | U4: 1.9071661 | V4: 2.3323739 | W4: 2.5704082 | X4: 2.5438011 | Y4: 4.4036 | Z4: 0.93336448 | AA4: 1 | AB4: 1.1259557 | AC4: 0.037325268 | AD4: 0.83598631 | AE4: 1.160177 | AF4: 2.5437047 | AG4: 10824.303
A5: 1.2883195 | B5: 1.5881146 | C5: 1 | D5: 0.30462764 | E5: 0.65418833 | F5: 0.81571258 | G5: 1.3178923 | H5: 1.112446 | I5: 0.32334112 | J5: 0.68525252 | K5: 1 | L5: 0.72026097 | M5: 1.2793036 | N5: 0.84149434 | O5: 1.1399313 | P5: 2.1282672 | Q5: 0.18116025 | R5: 0.29155201 | S5: 1 | T5: 1.2661953 | U5: 1.7931214 | V5: 2.2149822 | W5: 2.4331852 | X5: 2.3622794 | Y5: 5.2644199 | Z5: 1.7810601 | AA5: 1 | AB5: 1.3198434 | AC5: 0.10834753 | AD5: 1.0744695 | AE5: 1.4275846 | AF5: 3.219778 | AG5: 10802.893
A6: 1.2883195 | B6: 1.5881146 | C6: 1 | D6: 0.30462764 | E6: 0.65418833 | F6: 0.81571258 | G6: 1.3178923 | H6: 1.112446 | I6: 0.32334112 | J6: 0.68525252 | K6: 1 | L6: 0.72026097 | M6: 1.2793036 | N6: 0.84149434 | O6: 1.1399313 | P6: 2.1282672 | Q6: 0.18456624 | R6: 0.29619379 | S6: 1 | T6: 1.2815188 | U6: 1.805068 | V6: 2.2338819 | W6: 2.4661737 | X6: 2.393741 | Y6: 4.94799 | Z6: 1.6700104 | AA6: 1 | AB6: 1.243781 | AC6: 0.120298 | AD6: 1.0242029 | AE6: 1.3573647 | AF6: 3.0713854 | AG6: 10802.779
A7: 1.2883195 | B7: 1.5881146 | C7: 1 | D7: 0.30462764 | E7: 0.65418833 | F7: 0.81571258 | G7: 1.3178923 | H7: 1.112446 | I7: 0.32334112 | J7: 0.68525252 | K7: 1 | L7: 0.72026097 | M7: 1.2793036 | N7: 0.84149434 | O7: 1.1399313 | P7: 2.1282672 | Q7: 0.1795867 | R7: 0.28710988 | S7: 1 | T7: 1.2716575 | U7: 1.7993038 | V7: 2.224779 | W7: 2.4464809 | X7: 2.3702565 | Y7: 5.3949281 | Z7: 1.8650471 | AA7: 1 | AB7: 1.3110194 | AC7: 0.11353137 | AD7: 1.0599551 | AE7: 1.4198756 | AF7: 3.2217902 | AG7: 10804.022
A8: 1.2883195 | B8: 1.5881146 | C8: 1 | D8: 0.30462764 | E8: 0.65418833 | F8: 0.81571258 | G8: 1.3178923 | H8: 1.112446 | I8: 0.32334112 | J8: 0.68525252 | K8: 1 | L8: 0.72026097 | M8: 1.2793036 | N8: 0.84149434 | O8: 1.1399313 | P8: 2.1282672 | Q8: 0.18260496 | R8: 0.28587202 | S8: 1 | T8: 1.2819186 | U8: 1.819389 | V8: 2.2824355 | W8: 2.4860868 | X8: 2.4039882 | Y8: 4.9510073 | Z8: 1.8094528 | AA8: 1 | AB8: 1.2536583 | AC8: 0.10702127 | AD8: 0.90571896 | AE8: 1.3645868 | AF8: 3.0222056 | AG8: 10806.789
A9: 1.2883195 | B9: 1.5881146 | C9: 1 | D9: 0.30462764 | E9: 0.65418833 | F9: 0.81571258 | G9: 1.3178923 | H9: 1.112446 | I9: 0.32334112 | J9: 0.68525252 | K9: 1 | L9: 0.72026097 | M9: 1.2793036 | N9: 0.84149434 | O9: 1.1399313 | P9: 2.1282672 | Q9: 0.18105805 | R9: 0.29023783 | S9: 1 | T9: 1.2737812 | U9: 1.7920147 | V9: 2.2340262 | W9: 2.4697212 | X9: 2.3704967 | Y9: 5.2538547 | Z9: 1.7850891 | AA9: 1 | AB9: 1.2767622 | AC9: 0.14149601 | AD9: 1.0325717 | AE9: 1.3688989 | AF9: 3.1977792 | AG9: 10804.268
A10: 1.2883195 | B10: 1.5881146 | C10: 1 | D10: 0.30462764 | E10: 0.65418833 | F10: 0.81571258 | G10: 1.3178923 | H10: 1.112446 | I10: 0.32334112 | J10: 0.68525252 | K10: 1 | L10: 0.72026097 | M10: 1.2793036 | N10: 0.84149434 | O10: 1.1399313 | P10: 2.1282672 | Q10: 0.17848287 | R10: 0.28776794 | S10: 1 | T10: 1.2605586 | U10: 1.7895205 | V10: 2.2248687 | W10: 2.4262598 | X10: 2.3483859 | Y10: 5.4439923 | Z10: 1.8460138 | AA10: 1 | AB10: 1.3455941 | AC10: 0.11328266 | AD10: 1.0450585 | AE10: 1.4593624 | AF10: 3.2732801 | AG10: 10803.766
A11: 1.2883195 | B11: 1.5881146 | C11: 1 | D11: 0.30462764 | E11: 0.65418833 | F11: 0.81571258 | G11: 1.3178923 | H11: 1.112446 | I11: 0.32334112 | J11: 0.68525252 | K11: 1 | L11: 0.72026097 | M11: 1.2793036 | N11: 0.84149434 | O11: 1.1399313 | P11: 2.1282672 | Q11: 0.18249396 | R11: 0.29543943 | S11: 1 | T11: 1.2753522 | U11: 1.8121542 | V11: 2.2329284 | W11: 2.4566754 | X11: 2.3900136 | Y11: 5.1121152 | Z11: 1.7037639 | AA11: 1 | AB11: 1.2882268 | AC11: 0.090768665 | AD11: 1.0414412 | AE11: 1.37913 | AF11: 3.1112758 | AG11: 10802.574
A12: 1.2412975 | B12: 0.76869681 | C12: 1 | D12: 0.97820407 | E12: 0.7356072 | F12: 0.35638763 | G12: 0.97386917 | H12: 1.7044039 | I12: 0.6289006 | J12: 1.4785891 | K12: 1 | L12: 0.18605358 | M12: 0.42368424 | N12: 0.3656391 | O12: 0.8434365 | P12: 1.0323773 | Q12: 0.18449369 | R12: 0.30221957 | S12: 1 | T12: 1.2868103 | U12: 1.8218123 | V12: 2.2592661 | W12: 2.4852022 | X12: 2.4189887 | Y12: 4.8671021 | Z12: 1.5418082 | AA12: 1 | AB12: 1.225942 | AC12: 0.10902299 | AD12: 0.96543895 | AE12: 1.3303596 | AF12: 2.9698502 | AG12: 10802.932
A13: 1.2412975 | B13: 0.76869681 | C13: 1 | D13: 0.97820407 | E13: 0.7356072 | F13: 0.35638763 | G13: 0.97386917 | H13: 1.7044039 | I13: 0.6289006 | J13: 1.4785891 | K13: 1 | L13: 0.18605358 | M13: 0.42368424 | N13: 0.3656391 | O13: 0.8434365 | P13: 1.0323773 | Q13: 0.17900348 | R13: 0.28240765 | S13: 1 | T13: 1.2579239 | U13: 1.7797097 | V13: 2.2090238 | W13: 2.4175737 | X13: 2.3340452 | Y13: 5.5018172 | Z13: 1.9824225 | AA13: 1 | AB13: 1.3702039 | AC13: 0.11763884 | AD13: 1.0949123 | AE13: 1.4817838 | AF13: 3.3655285 | AG13: 10805.15
... A101: 0.19103755 | B101: 0.60596125 | C101: 1 | D101: 0.93763624 | E101: 0.70977082 | F101: 1.6797631 | G101: 0.87223289 | H101: 0.72932341 | I101: 1.524351 | J101: 0.81706952 | K101: 1 | L101: 0.55631967 | M101: 1.1017943 | N101: 0.49346278 | O101: 0.52694774 | P101: 0.73431475 | Q101: 0.18236421 | R101: 0.29008526 | S101: 1 | T101: 1.2708321 | U101: 1.7952071 | V101: 2.2334256 | W101: 2.4430048 | X101: 2.3616033 | Y101: 5.170171 | Z101: 1.8063243 | AA101: 1 | AB101: 1.3125929 | AC101: 0.11699047 | AD101: 1.0347699 | AE101: 1.4279554 | AF101: 3.2177027 | AG101: 10803.022

Sheet All trials
A1: s0-9i | B1: s10-19i | C1: s20-29i | D1: s30-39i | E1: s40-49i | F1: s50-59i | G1: s60-69i | H1: s70-79i | I1: v0-9i | J1: v10-19i | K1: s20-29i | L1: v30-39i | M1: v40-49i | N1: v50-59i | O1: v60-69i | P1: v70-79i | Q1: s0-9 | R1: s10-19 | S1: s20-29 | T1: s30-39 | U1: s40-49 | V1: s50-59 | W1: s60-69 | X1: s70-79 | Y1: v0-9 | Z1: v10-19 | AA1: s20-29 | AB1: v30-39 | AC1: v40-49 | AD1: v50-59 | AE1: v60-69 | AF1: v70-79 | AG1: kl_div | AH1: Log10(kl) | AI1: Best
A2: =(Untransformed!A98) -> 0.19103755 | B2: =(Untransformed!B98) -> 0.60596125 | C2: 1 | D2: =(Untransformed!D98) -> 0.93763624 | E2: =(Untransformed!E98) -> 0.70977082 | F2: =(Untransformed!F98) -> 1.6797631 | G2: =(Untransformed!G98) -> 0.87223289 | H2: =(Untransformed!H98) -> 0.72932341 | I2: =(Untransformed!I98) -> 1.524351 | J2: =(Untransformed!J98) -> 0.81706952 | K2: 1 | L2: =(Untransformed!L98) -> 0.55631967 | M2: =(Untransformed!M98) -> 1.1017943 | N2: =(Untransformed!N98) -> 0.49346278 | O2: =(Untransformed!O98) -> 0.52694774 | P2: =(Untransformed!P98) -> 0.73431475 | Q2: =(Untransformed!Q98) -> 0.18273963 | R2: =(Untransformed!R98) -> 0.29642921 | S2: 1 | T2: =(Untransformed!T98) -> 1.2744013 | U2: =(Untransformed!U98) -> 1.8055268 | V2: =(Untransformed!V98) -> 2.2343444 | W2: =(Untransformed!W98) -> 2.4558851 | X2: =(Untransformed!X98) -> 2.383999 | Y2: =(Untransformed!Y98) -> 5.0750012 | Z2: =(Untransformed!Z98) -> 1.6756666 | AA2: 1 | AB2: =(Untransformed!AB98) -> 1.2814424 | AC2: =(Untransformed!AC98) -> 0.10832239 | AD2: =(Untransformed!AD98) -> 1.0261647 | AE2: =(Untransformed!AE98) -> 1.3823864 | AF2: =(Untransformed!AF98) -> 3.1185226 | AG2: =(Untransformed!AG98) -> 10802.205 | AH2: =LOG10(AG2) -> 4.0335124 | AI2: 1
A3: =(Untransformed!A92) -> 0.19103755 | B3: =(Untransformed!B92) -> 0.60596125 | C3: 1 | D3: =(Untransformed!D92) -> 0.93763624 | E3: =(Untransformed!E92) -> 0.70977082 | F3: =(Untransformed!F92) -> 1.6797631 | G3: =(Untransformed!G92) -> 0.87223289 | H3: =(Untransformed!H92) -> 0.72932341 | I3: =(Untransformed!I92) -> 1.524351 | J3: =(Untransformed!J92) -> 0.81706952 | K3: 1 | L3: =(Untransformed!L92) -> 0.55631967 | M3: =(Untransformed!M92) -> 1.1017943 | N3: =(Untransformed!N92) -> 0.49346278 | O3: =(Untransformed!O92) -> 0.52694774 | P3: =(Untransformed!P92) -> 0.73431475 | Q3: =(Untransformed!Q92) -> 0.18167901 | R3: =(Untransformed!R92) -> 0.2957673 | S3: 1 | T3: =(Untransformed!T92) -> 1.27018 | U3: =(Untransformed!U92) -> 1.8032315 | V3: =(Untransformed!V92) -> 2.2208542 | W3: =(Untransformed!W92) -> 2.4429688 | X3: =(Untransformed!X92) -> 2.37492 | Y3: =(Untransformed!Y92) -> 5.1826102 | Z3: =(Untransformed!Z92) -> 1.7060613 | AA3: 1 | AB3: =(Untransformed!AB92) -> 1.3053214 | AC3: =(Untransformed!AC92) -> 0.098449146 | AD3: =(Untransformed!AD92) -> 1.0643692 | AE3: =(Untransformed!AE92) -> 1.4024799 | AF3: =(Untransformed!AF92) -> 3.1656047 | AG3: =(Untransformed!AG92) -> 10802.589 | AH3: =LOG10(AG3) -> 4.0335278
A4: =(Untransformed!A99) -> 0.19103755 | B4: =(Untransformed!B99) -> 0.60596125 | C4: 1 | D4: =(Untransformed!D99) -> 0.93763624 | E4: =(Untransformed!E99) -> 0.70977082 | F4: =(Untransformed!F99) -> 1.6797631 | G4: =(Untransformed!G99) -> 0.87223289 | H4: =(Untransformed!H99) -> 0.72932341 | I4: =(Untransformed!I99) -> 1.524351 | J4: =(Untransformed!J99) -> 0.81706952 | K4: 1 | L4: =(Untransformed!L99) -> 0.55631967 | M4: =(Untransformed!M99) -> 1.1017943 | N4: =(Untransformed!N99) -> 0.49346278 | O4: =(Untransformed!O99) -> 0.52694774 | P4: =(Untransformed!P99) -> 0.73431475 | Q4: =(Untransformed!Q99) -> 0.18283581 | R4: =(Untransformed!R99) -> 0.29461332 | S4: 1 | T4: =(Untransformed!T99) -> 1.2702549 | U4: =(Untransformed!U99) -> 1.7960938 | V4: =(Untransformed!V99) -> 2.2147044 | W4: =(Untransformed!W99) -> 2.4430793 | X4: =(Untransformed!X99) -> 2.3709371 | Y4: =(Untransformed!Y99) -> 5.140059 | Z4: =(Untransformed!Z99) -> 1.7482543 | AA4: 1 | AB4: =(Untransformed!AB99) -> 1.3075533 | AC4: =(Untransformed!AC99) -> 0.10733133 | AD4: =(Untransformed!AD99) -> 1.0844955 | AE4: =(Untransformed!AE99) -> 1.4053998 | AF4: =(Untransformed!AF99) -> 3.1947557 | AG4: =(Untransformed!AG99) -> 10802.863 | AH4: =LOG10(AG4) -> 4.0335389
A5: =(Untransformed!A101) -> 0.19103755 | B5: =(Untransformed!B101) -> 0.60596125 | C5: 1 | D5: =(Untransformed!D101) -> 0.93763624 | E5: =(Untransformed!E101) -> 0.70977082 | F5: =(Untransformed!F101) -> 1.6797631 | G5: =(Untransformed!G101) -> 0.87223289 | H5: =(Untransformed!H101) -> 0.72932341 | I5: =(Untransformed!I101) -> 1.524351 | J5: =(Untransformed!J101) -> 0.81706952 | K5: 1 | L5: =(Untransformed!L101) -> 0.55631967 | M5: =(Untransformed!M101) -> 1.1017943 | N5: =(Untransformed!N101) -> 0.49346278 | O5: =(Untransformed!O101) -> 0.52694774 | P5: =(Untransformed!P101) -> 0.73431475 | Q5: =(Untransformed!Q101) -> 0.18236421 | R5: =(Untransformed!R101) -> 0.29008526 | S5: 1 | T5: =(Untransformed!T101) -> 1.2708321 | U5: =(Untransformed!U101) -> 1.7952071 | V5: =(Untransformed!V101) -> 2.2334256 | W5: =(Untransformed!W101) -> 2.4430048 | X5: =(Untransformed!X101) -> 2.3616033 | Y5: =(Untransformed!Y101) -> 5.170171 | Z5: =(Untransformed!Z101) -> 1.8063243 | AA5: 1 | AB5: =(Untransformed!AB101) -> 1.3125929 | AC5: =(Untransformed!AC101) -> 0.11699047 | AD5: =(Untransformed!AD101) -> 1.0347699 | AE5: =(Untransformed!AE101) -> 1.4279554 | AF5: =(Untransformed!AF101) -> 3.2177027 | AG5: =(Untransformed!AG101) -> 10803.022 | AH5: =LOG10(AG5) -> 4.0335453
A6: =(Untransformed!A97) -> 0.19103755 | B6: =(Untransformed!B97) -> 0.60596125 | C6: 1 | D6: =(Untransformed!D97) -> 0.93763624 | E6: =(Untransformed!E97) -> 0.70977082 | F6: =(Untransformed!F97) -> 1.6797631 | G6: =(Untransformed!G97) -> 0.87223289 | H6: =(Untransformed!H97) -> 0.72932341 | I6: =(Untransformed!I97) -> 1.524351 | J6: =(Untransformed!J97) -> 0.81706952 | K6: 1 | L6: =(Untransformed!L97) -> 0.55631967 | M6: =(Untransformed!M97) -> 1.1017943 | N6: =(Untransformed!N97) -> 0.49346278 | O6: =(Untransformed!O97) -> 0.52694774 | P6: =(Untransformed!P97) -> 0.73431475 | Q6: =(Untransformed!Q97) -> 0.18607784 | R6: =(Untransformed!R97) -> 0.3044705 | S6: 1 | T6: =(Untransformed!T97) -> 1.2855903 | U6: =(Untransformed!U97) -> 1.8299409 | V6: =(Untransformed!V97) -> 2.2795415 | W6: =(Untransformed!W97) -> 2.4966273 | X6: =(Untransformed!X97) -> 2.420826 | Y6: =(Untransformed!Y97) -> 4.7080527 | Z6: =(Untransformed!Z97) -> 1.5220742 | AA6: 1 | AB6: =(Untransformed!AB97) -> 1.2381741 | AC6: =(Untransformed!AC97) -> 0.10666437 | AD6: =(Untransformed!AD97) -> 0.925823 | AE6: =(Untransformed!AE97) -> 1.3250555 | AF6: =(Untransformed!AF97) -> 2.9659267 | AG6: =(Untransformed!AG97) -> 10803.983 | AH6: =LOG10(AG6) -> 4.0335839
A7: =(Untransformed!A94) -> 0.19103755 | B7: =(Untransformed!B94) -> 0.60596125 | C7: 1 | D7: =(Untransformed!D94) -> 0.93763624 | E7: =(Untransformed!E94) -> 0.70977082 | F7: =(Untransformed!F94) -> 1.6797631 | G7: =(Untransformed!G94) -> 0.87223289 | H7: =(Untransformed!H94) -> 0.72932341 | I7: =(Untransformed!I94) -> 1.524351 | J7: =(Untransformed!J94) -> 0.81706952 | K7: 1 | L7: =(Untransformed!L94) -> 0.55631967 | M7: =(Untransformed!M94) -> 1.1017943 | N7: =(Untransformed!N94) -> 0.49346278 | O7: =(Untransformed!O94) -> 0.52694774 | P7: =(Untransformed!P94) -> 0.73431475 | Q7: =(Untransformed!Q94) -> 0.17997893 | R7: =(Untransformed!R94) -> 0.28875675 | S7: 1 | T7: =(Untransformed!T94) -> 1.2598197 | U7: =(Untransformed!U94) -> 1.7769559 | V7: =(Untransformed!V94) -> 2.2187032 | W7: =(Untransformed!W94) -> 2.4212954 | X7: =(Untransformed!X94) -> 2.3354298 | Y7: =(Untransformed!Y94) -> 5.3571361 | Z7: =(Untransformed!Z94) -> 1.8321578 | AA7: 1 | AB7: =(Untransformed!AB94) -> 1.3435553 | AC7: =(Untransformed!AC94) -> 0.14155583 | AD7: =(Untransformed!AD94) -> 1.0500855 | AE7: =(Untransformed!AE94) -> 1.4745232 | AF7: =(Untransformed!AF94) -> 3.316573 | AG7: =(Untransformed!AG94) -> 10804.145 | AH7: =LOG10(AG7) -> 4.0335904
A8: =(Untransformed!A93) -> 0.19103755 | B8: =(Untransformed!B93) -> 0.60596125 | C8: 1 | D8: =(Untransformed!D93) -> 0.93763624 | E8: =(Untransformed!E93) -> 0.70977082 | F8: =(Untransformed!F93) -> 1.6797631 | G8: =(Untransformed!G93) -> 0.87223289 | H8: =(Untransformed!H93) -> 0.72932341 | I8: =(Untransformed!I93) -> 1.524351 | J8: =(Untransformed!J93) -> 0.81706952 | K8: 1 | L8: =(Untransformed!L93) -> 0.55631967 | M8: =(Untransformed!M93) -> 1.1017943 | N8: =(Untransformed!N93) -> 0.49346278 | O8: =(Untransformed!O93) -> 0.52694774 | P8: =(Untransformed!P93) -> 0.73431475 | Q8: =(Untransformed!Q93) -> 0.18558184 | R8: =(Untransformed!R93) -> 0.38482341 | S8: 1 | T8: =(Untransformed!T93) -> 1.3335884 | U8: =(Untransformed!U93) -> 1.9390317 | V8: =(Untransformed!V93) -> 2.4708859 | W8: =(Untransformed!W93) -> 2.7053507 | X8: =(Untransformed!X93) -> 2.6669983 | Y8: =(Untransformed!Y93) -> 4.2652043 | Z8: =(Untransformed!Z93) -> 0.51448019 | AA8: 1 | AB8: =(Untransformed!AB93) -> 1.0540426 | AC8: =(Untransformed!AC93) -> 0.11624685 | AD8: =(Untransformed!AD93) -> 0.60167928 | AE8: =(Untransformed!AE93) -> 1.0531953 | AF8: =(Untransformed!AF93) -> 2.3069443 | AG8: =(Untransformed!AG93) -> 10867.776 | AH8: =LOG10(AG8) -> 4.0361407
A9: =(Untransformed!A95) -> 0.19103755 | B9: =(Untransformed!B95) -> 0.60596125 | C9: 1 | D9: =(Untransformed!D95) -> 0.93763624 | E9: =(Untransformed!E95) -> 0.70977082 | F9: =(Untransformed!F95) -> 1.6797631 | G9: =(Untransformed!G95) -> 0.87223289 | H9: =(Untransformed!H95) -> 0.72932341 | I9: =(Untransformed!I95) -> 1.524351 | J9: =(Untransformed!J95) -> 0.81706952 | K9: 1 | L9: =(Untransformed!L95) -> 0.55631967 | M9: =(Untransformed!M95) -> 1.1017943 | N9: =(Untransformed!N95) -> 0.49346278 | O9: =(Untransformed!O95) -> 0.52694774 | P9: =(Untransformed!P95) -> 0.73431475 | Q9: =(Untransformed!Q95) -> 0.34918641 | R9: =(Untransformed!R95) -> 0.273919 | S9: 1 | T9: =(Untransformed!T95) -> 1.6307879 | U9: =(Untransformed!U95) -> 1.7588807 | V9: =(Untransformed!V95) -> 2.153315 | W9: =(Untransformed!W95) -> 2.9363009 | X9: =(Untransformed!X95) -> 2.7211127 | Y9: =(Untransformed!Y95) -> 0.085475863 | Z9: =(Untransformed!Z95) -> 2.2432322 | AA9: 1 | AB9: =(Untransformed!AB95) -> 0.24364716 | AC9: =(Untransformed!AC95) -> 0.45453141 | AD9: =(Untransformed!AD95) -> 1.24902 | AE9: =(Untransformed!AE95) -> 0.62528855 | AF9: =(Untransformed!AF95) -> 2.076167 | AG9: =(Untransformed!AG95) -> 12109.201 | AH9: =LOG10(AG9) -> 4.0831155
A10: =(Untransformed!A96) -> 0.19103755 | B10: =(Untransformed!B96) -> 0.60596125 | C10: 1 | D10: =(Untransformed!D96) -> 0.93763624 | E10: =(Untransformed!E96) -> 0.70977082 | F10: =(Untransformed!F96) -> 1.6797631 | G10: =(Untransformed!G96) -> 0.87223289 | H10: =(Untransformed!H96) -> 0.72932341 | I10: =(Untransformed!I96) -> 1.524351 | J10: =(Untransformed!J96) -> 0.81706952 | K10: 1 | L10: =(Untransformed!L96) -> 0.55631967 | M10: =(Untransformed!M96) -> 1.1017943 | N10: =(Untransformed!N96) -> 0.49346278 | O10: =(Untransformed!O96) -> 0.52694774 | P10: =(Untransformed!P96) -> 0.73431475 | Q10: =(Untransformed!Q96) -> 0.29388079 | R10: =(Untransformed!R96) -> 0.2712411 | S10: 1 | T10: =(Untransformed!T96) -> 1.3002391 | U10: =(Untransformed!U96) -> 1.8430031 | V10: =(Untransformed!V96) -> 2.5071387 | W10: =(Untransformed!W96) -> 2.3688608 | X10: =(Untransformed!X96) -> 3.6422011 | Y10: =(Untransformed!Y96) -> 3.6161465e-06 | Z10: =(Untransformed!Z96) -> 0.045606894 | AA10: 1 | AB10: =(Untransformed!AB96) -> 0.70932556 | AC10: =(Untransformed!AC96) -> 0.24001603 | AD10: =(Untransformed!AD96) -> 1.1808471e-05 | AE10: =(Untransformed!AE96) -> 1.7764485 | AF10: =(Untransformed!AF96) -> 0.063172463 | AG10: =(Untransformed!AG96) -> 17447.876 | AH10: =LOG10(AG10) -> 4.2417426
A11: =(Untransformed!A100) -> 0.19103755 | B11: =(Untransformed!B100) -> 0.60596125 | C11: 1 | D11: =(Untransformed!D100) -> 0.93763624 | E11: =(Untransformed!E100) -> 0.70977082 | F11: =(Untransformed!F100) -> 1.6797631 | G11: =(Untransformed!G100) -> 0.87223289 | H11: =(Untransformed!H100) -> 0.72932341 | I11: =(Untransformed!I100) -> 1.524351 | J11: =(Untransformed!J100) -> 0.81706952 | K11: 1 | L11: =(Untransformed!L100) -> 0.55631967 | M11: =(Untransformed!M100) -> 1.1017943 | N11: =(Untransformed!N100) -> 0.49346278 | O11: =(Untransformed!O100) -> 0.52694774 | P11: =(Untransformed!P100) -> 0.73431475 | Q11: =(Untransformed!Q100) -> 0.10919023 | R11: =(Untransformed!R100) -> 0.27335776 | S11: 1 | T11: =(Untransformed!T100) -> 1.1864385 | U11: =(Untransformed!U100) -> 1.2670474 | V11: =(Untransformed!V100) -> 1.8577679 | W11: =(Untransformed!W100) -> 1.892322 | X11: =(Untransformed!X100) -> 2.2053808 | Y11: =(Untransformed!Y100) -> 0.00012091324 | Z11: =(Untransformed!Z100) -> 0.083730468 | AA11: 1 | AB11: =(Untransformed!AB100) -> 0.10354982 | AC11: =(Untransformed!AC100) -> 0.70713842 | AD11: =(Untransformed!AD100) -> 0.00022052453 | AE11: =(Untransformed!AE100) -> 1.9095077 | AF11: =(Untransformed!AF100) -> 0.44617508 | AG11: =(Untransformed!AG100) -> 21582.081 | AH11: =LOG10(AG11) -> 4.3340933
A12: =(Untransformed!A53) -> 0.66171329 | B12: =(Untransformed!B53) -> 1.4989558 | C12: 1 | D12: =(Untransformed!D53) -> 0.2846583 | E12: =(Untransformed!E53) -> 0.94904862 | F12: =(Untransformed!F53) -> 0.40859493 | G12: =(Untransformed!G53) -> 1.2419868 | H12: =(Untransformed!H53) -> 0.85690348 | I12: =(Untransformed!I53) -> 0.76364275 | J12: =(Untransformed!J53) -> 0.6449456 | K12: 1 | L12: =(Untransformed!L53) -> 0.97693163 | M12: =(Untransformed!M53) -> 0.9428961 | N12: =(Untransformed!N53) -> 1.3976706 | O12: =(Untransformed!O53) -> 0.88298659 | P12: =(Untransformed!P53) -> 1.1975141 | Q12: =(Untransformed!Q53) -> 0.18249529 | R12: =(Untransformed!R53) -> 0.29774209 | S12: 1 | T12: =(Untransformed!T53) -> 1.2755465 | U12: =(Untransformed!U53) -> 1.8050698 | V12: =(Untransformed!V53) -> 2.2364647 | W12: =(Untransformed!W53) -> 2.4625077 | X12: =(Untransformed!X53) -> 2.3853596 | Y12: =(Untransformed!Y53) -> 5.0976164 | Z12: =(Untransformed!Z53) -> 1.6455982 | AA12: 1 | AB12: =(Untransformed!AB53) -> 1.2689086 | AC12: =(Untransformed!AC53) -> 0.11454424 | AD12: =(Untransformed!AD53) -> 1.0177027 | AE12: =(Untransformed!AE53) -> 1.3676879 | AF12: =(Untransformed!AF53) -> 3.1078517 | AG12: =(Untransformed!AG53) -> 10802.267 | AH12: =LOG10(AG12) -> 4.0335149 | AI12: 1
A13: =(Untransformed!A56) -> 0.66171329 | B13: =(Untransformed!B56) -> 1.4989558 | C13: 1 | D13: =(Untransformed!D56) -> 0.2846583 | E13: =(Untransformed!E56) -> 0.94904862 | F13: =(Untransformed!F56) -> 0.40859493 | G13: =(Untransformed!G56) -> 1.2419868 | H13: =(Untransformed!H56) -> 0.85690348 | I13: =(Untransformed!I56) -> 0.76364275 | J13: =(Untransformed!J56) -> 0.6449456 | K13: 1 | L13: =(Untransformed!L56) -> 0.97693163 | M13: =(Untransformed!M56) -> 0.9428961 | N13: =(Untransformed!N56) -> 1.3976706 | O13: =(Untransformed!O56) -> 0.88298659 | P13: =(Untransformed!P56) -> 1.1975141 | Q13: =(Untransformed!Q56) -> 0.18308562 | R13: =(Untransformed!R56) -> 0.29843678 | S13: 1 | T13: =(Untransformed!T56) -> 1.2789364 | U13: =(Untransformed!U56) -> 1.8139033 | V13: =(Untransformed!V56) -> 2.238564 | W13: =(Untransformed!W56) -> 2.4678017 | X13: =(Untransformed!X56) -> 2.3999668 | Y13: =(Untransformed!Y56) -> 5.0469886 | Z13: =(Untransformed!Z56) -> 1.6386518 | AA13: 1 | AB13: =(Untransformed!AB56) -> 1.2645695 | AC13: =(Untransformed!AC56) -> 0.099748796 | AD13: =(Untransformed!AD56) -> 1.0242277 | AE13: =(Untransformed!AE56) -> 1.3530655 | AF13: =(Untransformed!AF56) -> 3.069388 | AG13: =(Untransformed!AG56) -> 10802.278 | AH13: =LOG10(AG13) -> 4.0335153
A14: =(Untransformed!A60) -> 0.66171329 | B14: =(Untransformed!B60) -> 1.4989558 | C14: 1 | D14: =(Untransformed!D60) -> 0.2846583 | E14: =(Untransformed!E60) -> 0.94904862 | F14: =(Untransformed!F60) -> 0.40859493 | G14: =(Untransformed!G60) -> 1.2419868 | H14: =(Untransformed!H60) -> 0.85690348 | I14: =(Untransformed!I60) -> 0.76364275 | J14: =(Untransformed!J60) -> 0.6449456 | K14: 1 | L14: =(Untransformed!L60) -> 0.97693163 | M14: =(Untransformed!M60) -> 0.9428961 | N14: =(Untransformed!N60) -> 1.3976706 | O14: =(Untransformed!O60) -> 0.88298659 | P14: =(Untransformed!P60) -> 1.1975141 | Q14: =(Untransformed!Q60) -> 0.18124718 | R14: =(Untransformed!R60) -> 0.29368315 | S14: 1 | T14: =(Untransformed!T60) -> 1.2682205 | U14: =(Untransformed!U60) -> 1.7938533 | V14: =(Untransformed!V60) -> 2.2240356 | W14: =(Untransformed!W60) -> 2.4410849 | X14: =(Untransformed!X60) -> 2.3630668 | Y14: =(Untransformed!Y60) -> 5.2235667 | Z14: =(Untransformed!Z60) -> 1.731965 | AA14: 1 | AB14: =(Untransformed!AB60) -> 1.3063985 | AC14: =(Untransformed!AC60) -> 0.1186488 | AD14: =(Untransformed!AD60) -> 1.0465708 | AE14: =(Untransformed!AE60) -> 1.4147676 | AF14: =(Untransformed!AF60) -> 3.202243 | AG14: =(Untransformed!AG60) -> 10802.595 | AH14: =LOG10(AG14) -> 4.0335281
A15: =(Untransformed!A52) -> 0.66171329 | B15: =(Untransformed!B52) -> 1.4989558 | C15: 1 | D15: =(Untransformed!D52) -> 0.2846583 | E15: =(Untransformed!E52) -> 0.94904862 | F15: =(Untransformed!F52) -> 0.40859493 | G15: =(Untransformed!G52) -> 1.2419868 | H15: =(Untransformed!H52) -> 0.85690348 | I15: =(Untransformed!I52) -> 0.76364275 | J15: =(Untransformed!J52) -> 0.6449456 | K15: 1 | L15: =(Untransformed!L52) -> 0.97693163 | M15: =(Untransformed!M52) -> 0.9428961 | N15: =(Untransformed!N52) -> 1.3976706 | O15: =(Untransformed!O52) -> 0.88298659 | P15: =(Untransformed!P52) -> 1.1975141 | Q15: =(Untransformed!Q52) -> 0.18387568 | R15: =(Untransformed!R52) -> 0.29156919 | S15: 1 | T15: =(Untransformed!T52) -> 1.2714272 | U15: =(Untransformed!U52) -> 1.79725 | V15: =(Untransformed!V52) -> 2.2290692 | W15: =(Untransformed!W52) -> 2.4457167 | X15: =(Untransformed!X52) -> 2.3694281 | Y15: =(Untransformed!Y52) -> 5.0975879 | Z15: =(Untransformed!Z52) -> 1.7822924 | AA15: 1 | AB15: =(Untransformed!AB52) -> 1.305165 | AC15: =(Untransformed!AC52) -> 0.11588855 | AD15: =(Untransformed!AD52) -> 1.0484945 | AE15: =(Untransformed!AE52) -> 1.4130814 | AF15: =(Untransformed!AF52) -> 3.1945075 | AG15: =(Untransformed!AG52) -> 10802.901 | AH15: =LOG10(AG15) -> 4.0335404
A16: =(Untransformed!A61) -> 0.66171329 | B16: =(Untransformed!B61) -> 1.4989558 | C16: 1 | D16: =(Untransformed!D61) -> 0.2846583 | E16: =(Untransformed!E61) -> 0.94904862 | F16: =(Untransformed!F61) -> 0.40859493 | G16: =(Untransformed!G61) -> 1.2419868 | H16: =(Untransformed!H61) -> 0.85690348 | I16: =(Untransformed!I61) -> 0.76364275 | J16: =(Untransformed!J61) -> 0.6449456 | K16: 1 | L16: =(Untransformed!L61) -> 0.97693163 | M16: =(Untransformed!M61) -> 0.9428961 | N16: =(Untransformed!N61) -> 1.3976706 | O16: =(Untransformed!O61) -> 0.88298659 | P16: =(Untransformed!P61) -> 1.1975141 | Q16: =(Untransformed!Q61) -> 0.18131237 | R16: =(Untransformed!R61) -> 0.29459081 | S16: 1 | T16: =(Untransformed!T61) -> 1.2684577 | U16: =(Untransformed!U61) -> 1.8078137 | V16: =(Untransformed!V61) -> 2.228221 | W16: =(Untransformed!W61) -> 2.443717 | X16: =(Untransformed!X61) -> 2.3771907 | Y16: =(Untransformed!Y61) -> 5.2079389 | Z16: =(Untransformed!Z61) -> 1.7244124 | AA16: 1 | AB16: =(Untransformed!AB61) -> 1.3177235 | AC16: =(Untransformed!AC61) -> 0.087863071 | AD16: =(Untransformed!AD61) -> 1.050687 | AE16: =(Untransformed!AE61) -> 1.4067185 | AF16: =(Untransformed!AF61) -> 3.1630909 | AG16: =(Untransformed!AG61) -> 10802.94 | AH16: =LOG10(AG16) -> 4.033542
A17: =(Untransformed!A57) -> 0.66171329 | B17: =(Untransformed!B57) -> 1.4989558 | C17: 1 | D17: =(Untransformed!D57) -> 0.2846583 | E17: =(Untransformed!E57) -> 0.94904862 | F17: =(Untransformed!F57) -> 0.40859493 | G17: =(Untransformed!G57) -> 1.2419868 | H17: =(Untransformed!H57) -> 0.85690348 | I17: =(Untransformed!I57) -> 0.76364275 | J17: =(Untransformed!J57) -> 0.6449456 | K17: 1 | L17: =(Untransformed!L57) -> 0.97693163 | M17: =(Untransformed!M57) -> 0.9428961 | N17: =(Untransformed!N57) -> 1.3976706 | O17: =(Untransformed!O57) -> 0.88298659 | P17: =(Untransformed!P57) -> 1.1975141 | Q17: =(Untransformed!Q57) -> 0.17935591 | R17: =(Untransformed!R57) -> 0.29057605 | S17: 1 | T17: =(Untransformed!T57) -> 1.2620632 | U17: =(Untransformed!U57) -> 1.7841612 | V17: =(Untransformed!V57) -> 2.2155624 | W17: =(Untransformed!W57) -> 2.4251942 | X17: =(Untransformed!X57) -> 2.348254 | Y17: =(Untransformed!Y57) -> 5.4121936 | Z17: =(Untransformed!Z57) -> 1.8088803 | AA17: 1 | AB17: =(Untransformed!AB57) -> 1.3391652 | AC17: =(Untransformed!AC57) -> 0.12342622 | AD17: =(Untransformed!AD57) -> 1.0702867 | AE17: =(Untransformed!AE57) -> 1.4556944 | AF17: =(Untransformed!AF57) -> 3.283307 | AG17: =(Untransformed!AG57) -> 10803.693 | AH17: =LOG10(AG17) -> 4.0335722
A18: =(Untransformed!A55) -> 0.66171329 | B18: =(Untransformed!B55) -> 1.4989558 | C18: 1 | D18: =(Untransformed!D55) -> 0.2846583 | E18: =(Untransformed!E55) -> 0.94904862 | F18: =(Untransformed!F55) -> 0.40859493 | G18: =(Untransformed!G55) -> 1.2419868 | H18: =(Untransformed!H55) -> 0.85690348 | I18: =(Untransformed!I55) -> 0.76364275 | J18: =(Untransformed!J55) -> 0.6449456 | K18: 1 | L18: =(Untransformed!L55) -> 0.97693163 | M18: =(Untransformed!M55) -> 0.9428961 | N18: =(Untransformed!N55) -> 1.3976706 | O18: =(Untransformed!O55) -> 0.88298659 | P18: =(Untransformed!P55) -> 1.1975141 | Q18: =(Untransformed!Q55) -> 0.18721481 | R18: =(Untransformed!R55) -> 0.3083771 | S18: 1 | T18: =(Untransformed!T55) -> 1.2888341 | U18: =(Untransformed!U55) -> 1.8295265 | V18: =(Untransformed!V55) -> 2.2548611 | W18: =(Untransformed!W55) -> 2.4954418 | X18: =(Untransformed!X55) -> 2.431778 | Y18: =(Untransformed!Y55) -> 4.6914925 | Z18: =(Untransformed!Z55) -> 1.4463605 | AA18: 1 | AB18: =(Untransformed!AB55) -> 1.2058067 | AC18: =(Untransformed!AC55) -> 0.098788379 | AD18: =(Untransformed!AD55) -> 0.97448488 | AE18: =(Untransformed!AE55) -> 1.2897224 | AF18: =(Untransformed!AF55) -> 2.9129915 | AG18: =(Untransformed!AG55) -> 10803.957 | AH18: =LOG10(AG18) -> 4.0335829
A19: =(Untransformed!A54) -> 0.66171329 | B19: =(Untransformed!B54) -> 1.4989558 | C19: 1 | D19: =(Untransformed!D54) -> 0.2846583 | E19: =(Untransformed!E54) -> 0.94904862 | F19: =(Untransformed!F54) -> 0.40859493 | G19: =(Untransformed!G54) -> 1.2419868 | H19: =(Untransformed!H54) -> 0.85690348 | I19: =(Untransformed!I54) -> 0.76364275 | J19: =(Untransformed!J54) -> 0.6449456 | K19: 1 | L19: =(Untransformed!L54) -> 0.97693163 | M19: =(Untransformed!M54) -> 0.9428961 | N19: =(Untransformed!N54) -> 1.3976706 | O19: =(Untransformed!O54) -> 0.88298659 | P19: =(Untransformed!P54) -> 1.1975141 | Q19: =(Untransformed!Q54) -> 0.17965474 | R19: =(Untransformed!R54) -> 0.28711234 | S19: 1 | T19: =(Untransformed!T54) -> 1.2525232 | U19: =(Untransformed!U54) -> 1.7963093 | V19: =(Untransformed!V54) -> 2.2041902 | W19: =(Untransformed!W54) -> 2.3908007 | X19: =(Untransformed!X54) -> 2.3250618 | Y19: =(Untransformed!Y54) -> 5.418436 | Z19: =(Untransformed!Z54) -> 1.9013396 | AA19: 1 | AB19: =(Untransformed!AB54) -> 1.4083202 | AC19: =(Untransformed!AC54) -> 0.065645901 | AD19: =(Untransformed!AD54) -> 1.1068386 | AE19: =(Untransformed!AE54) -> 1.5181577 | AF19: =(Untransformed!AF54) -> 3.3571759 | AG19: =(Untransformed!AG54) -> 10807.5 | AH19: =LOG10(AG19) -> 4.0337252
A20: =(Untransformed!A59) -> 0.66171329 | B20: =(Untransformed!B59) -> 1.4989558 | C20: 1 | D20: =(Untransformed!D59) -> 0.2846583 | E20: =(Untransformed!E59) -> 0.94904862 | F20: =(Untransformed!F59) -> 0.40859493 | G20: =(Untransformed!G59) -> 1.2419868 | H20: =(Untransformed!H59) -> 0.85690348 | I20: =(Untransformed!I59) -> 0.76364275 | J20: =(Untransformed!J59) -> 0.6449456 | K20: 1 | L20: =(Untransformed!L59) -> 0.97693163 | M20: =(Untransformed!M59) -> 0.9428961 | N20: =(Untransformed!N59) -> 1.3976706 | O20: =(Untransformed!O59) -> 0.88298659 | P20: =(Untransformed!P59) -> 1.1975141 | Q20: =(Untransformed!Q59) -> 0.19322801 | R20: =(Untransformed!R59) -> 0.4247417 | S20: 1 | T20: =(Untransformed!T59) -> 1.3526956 | U20: =(Untransformed!U59) -> 1.9878793 | V20: =(Untransformed!V59) -> 2.3363413 | W20: =(Untransformed!W59) -> 2.6676449 | X20: =(Untransformed!X59) -> 2.7018867 | Y20: =(Untransformed!Y59) -> 4.167295 | Z20: =(Untransformed!Z59) -> 0.23932196 | AA20: 1 | AB20: =(Untransformed!AB59) -> 0.99602186 | AC20: =(Untransformed!AC59) -> 4.4548552e-05 | AD20: =(Untransformed!AD59) -> 0.88085413 | AE20: =(Untransformed!AE59) -> 0.95169587 | AF20: =(Untransformed!AF59) -> 2.1941978 | AG20: =(Untransformed!AG59) -> 10887.475 | AH20: =LOG10(AG20) -> 4.0369272
A21: =(Untransformed!A58) -> 0.66171329 | B21: =(Untransformed!B58) -> 1.4989558 | C21: 1 | D21: =(Untransformed!D58) -> 0.2846583 | E21: =(Untransformed!E58) -> 0.94904862 | F21: =(Untransformed!F58) -> 0.40859493 | G21: =(Untransformed!G58) -> 1.2419868 | H21: =(Untransformed!H58) -> 0.85690348 | I21: =(Untransformed!I58) -> 0.76364275 | J21: =(Untransformed!J58) -> 0.6449456 | K21: 1 | L21: =(Untransformed!L58) -> 0.97693163 | M21: =(Untransformed!M58) -> 0.9428961 | N21: =(Untransformed!N58) -> 1.3976706 | O21: =(Untransformed!O58) -> 0.88298659 | P21: =(Untransformed!P58) -> 1.1975141 | Q21: =(Untransformed!Q58) -> 0.2292047 | R21: =(Untransformed!R58) -> 0.41791381 | S21: 1 | T21: =(Untransformed!T58) -> 1.443179 | U21: =(Untransformed!U58) -> 2.0196732 | V21: =(Untransformed!V58) -> 2.4384897 | W21: =(Untransformed!W58) -> 2.8978884 | X21: =(Untransformed!X58) -> 2.892272 | Y21: =(Untransformed!Y58) -> 2.5949945 | Z21: =(Untransformed!Z58) -> 0.40007066 | AA21: 1 | AB21: =(Untransformed!AB58) -> 0.77029475 | AC21: =(Untransformed!AC58) -> 0.078029028 | AD21: =(Untransformed!AD58) -> 0.73016825 | AE21: =(Untransformed!AE58) -> 0.74941375 | AF21: =(Untransformed!AF58) -> 1.8535732 | AG21: =(Untransformed!AG58) -> 10946.154 | AH21: =LOG10(AG21) -> 4.0392616
A22: =(Untransformed!A87) -> 0.66419438 | B22: =(Untransformed!B87) -> 1.2567213 | C22: 1 | D22: =(Untransformed!D87) -> 0.90194986 | E22: =(Untransformed!E87) -> 0.84581538 | F22: =(Untransformed!F87) -> 0.7767185 | G22: =(Untransformed!G87) -> 1.0700111 | H22: =(Untransformed!H87) -> 0.84812952 | I22: =(Untransformed!I87) -> 1.4687262 | J22: =(Untransformed!J87) -> 1.9387914 | K22: 1 | L22: =(Untransformed!L87) -> 0.69554684 | M22: =(Untransformed!M87) -> 1.0384404 | N22: =(Untransformed!N87) -> 0.38832374 | O22: =(Untransformed!O87) -> 0.78101017 | P22: =(Untransformed!P87) -> 0.40777436 | Q22: =(Untransformed!Q87) -> 0.18190649 | R22: =(Untransformed!R87) -> 0.29909161 | S22: 1 | T22: =(Untransformed!T87) -> 1.2771333 | U22: =(Untransformed!U87) -> 1.8105405 | V22: =(Untransformed!V87) -> 2.2381679 | W22: =(Untransformed!W87) -> 2.4656863 | X22: =(Untransformed!X87) -> 2.3958739 | Y22: =(Untransformed!Y87) -> 5.0941734 | Z22: =(Untransformed!Z87) -> 1.6062023 | AA22: 1 | AB22: =(Untransformed!AB87) -> 1.2570224 | AC22: =(Untransformed!AC87) -> 0.10409633 | AD22: =(Untransformed!AD87) -> 1.0134335 | AE22: =(Untransformed!AE87) -> 1.3521579 | AF22: =(Untransformed!AF87) -> 3.0587113 | AG22: =(Untransformed!AG87) -> 10802.369 | AH22: =LOG10(AG22) -> 4.033519
A23: =(Untransformed!A89) -> 0.66419438 | B23: =(Untransformed!B89) -> 1.2567213 | C23: 1 | D23: =(Untransformed!D89) -> 0.90194986 | E23: =(Untransformed!E89) -> 0.84581538 | F23: =(Untransformed!F89) -> 0.7767185 | G23: =(Untransformed!G89) -> 1.0700111 | H23: =(Untransformed!H89) -> 0.84812952 | I23: =(Untransformed!I89) -> 1.4687262 | J23: =(Untransformed!J89) -> 1.9387914 | K23: 1 | L23: =(Untransformed!L89) -> 0.69554684 | M23: =(Untransformed!M89) -> 1.0384404 | N23: =(Untransformed!N89) -> 0.38832374 | O23: =(Untransformed!O89) -> 0.78101017 | P23: =(Untransformed!P89) -> 0.40777436 | Q23: =(Untransformed!Q89) -> 0.18353991 | R23: =(Untransformed!R89) -> 0.30039464 | S23: 1 | T23: =(Untransformed!T89) -> 1.2734232 | U23: =(Untransformed!U89) -> 1.8096814 | V23: =(Untransformed!V89) -> 2.226145 | W23: =(Untransformed!W89) -> 2.4505811 | X23: =(Untransformed!X89) -> 2.3821806 | Y23: =(Untransformed!Y89) -> 5.0827644 | Z23: =(Untransformed!Z89) -> 1.6054632 | AA23: 1 | AB23: =(Untransformed!AB89) -> 1.2753206 | AC23: =(Untransformed!AC89) -> 0.10043799 | AD23: =(Untransformed!AD89) -> 1.0436962 | AE23: =(Untransformed!AE89) -> 1.3714431 | AF23: =(Untransformed!AF89) -> 3.107769 | AG23: =(Untransformed!AG89) -> 10802.638 | AH23: =LOG10(AG23) -> 4.0335298 | AI23: 1
A24: =(Untransformed!A84) -> 0.66419438 | B24: =(Untransformed!B84) -> 1.2567213 | C24: 1 | D24: =(Untransformed!D84) -> 0.90194986 | E24: =(Untransformed!E84) -> 0.84581538 | F24: =(Untransformed!F84) -> 0.7767185 | G24: =(Untransformed!G84) -> 1.0700111 | H24: =(Untransformed!H84) -> 0.84812952 | I24: =(Untransformed!I84) -> 1.4687262 | J24: =(Untransformed!J84) -> 1.9387914 | K24: 1 | L24: =(Untransformed!L84) -> 0.69554684 | M24: =(Untransformed!M84) -> 1.0384404 | N24: =(Untransformed!N84) -> 0.38832374 | O24: =(Untransformed!O84) -> 0.78101017 | P24: =(Untransformed!P84) -> 0.40777436 | Q24: =(Untransformed!Q84) -> 0.18406078 | R24: =(Untransformed!R84) -> 0.29828755 | S24: 1 | T24: =(Untransformed!T84) -> 1.2749193 | U24: =(Untransformed!U84) -> 1.8094235 | V24: =(Untransformed!V84) -> 2.2223269 | W24: =(Untransformed!W84) -> 2.4590085 | X24: =(Untransformed!X84) -> 2.3928356 | Y24: =(Untransformed!Y84) -> 5.0354677 | Z24: =(Untransformed!Z84) -> 1.6624777 | AA24: 1 | AB24: =(Untransformed!AB84) -> 1.285804 | AC24: =(Untransformed!AC84) -> 0.095374134 | AD24: =(Untransformed!AD84) -> 1.0719 | AE24: =(Untransformed!AE84) -> 1.3605721 | AF24: =(Untransformed!AF84) -> 3.1189487 | AG24: =(Untransformed!AG84) -> 10802.699 | AH24: =LOG10(AG24) -> 4.0335323
A25: =(Untransformed!A86) -> 0.66419438 | B25: =(Untransformed!B86) -> 1.2567213 | C25: 1 | D25: =(Untransformed!D86) -> 0.90194986 | E25: =(Untransformed!E86) -> 0.84581538 | F25: =(Untransformed!F86) -> 0.7767185 | G25: =(Untransformed!G86) -> 1.0700111 | H25: =(Untransformed!H86) -> 0.84812952 | I25: =(Untransformed!I86) -> 1.4687262 | J25: =(Untransformed!J86) -> 1.9387914 | K25: 1 | L25: =(Untransformed!L86) -> 0.69554684 | M25: =(Untransformed!M86) -> 1.0384404 | N25: =(Untransformed!N86) -> 0.38832374 | O25: =(Untransformed!O86) -> 0.78101017 | P25: =(Untransformed!P86) -> 0.40777436 | Q25: =(Untransformed!Q86) -> 0.18467109 | R25: =(Untransformed!R86) -> 0.30095298 | S25: 1 | T25: =(Untransformed!T86) -> 1.2820884 | U25: =(Untransformed!U86) -> 1.8041068 | V25: =(Untransformed!V86) -> 2.2608433 | W25: =(Untransformed!W86) -> 2.4901251 | X25: =(Untransformed!X86) -> 2.4014101 | Y25: =(Untransformed!Y86) -> 4.8100556 | Z25: =(Untransformed!Z86) -> 1.5750412 | AA25: 1 | AB25: =(Untransformed!AB86) -> 1.234862 | AC25: =(Untransformed!AC86) -> 0.14046749 | AD25: =(Untransformed!AD86) -> 0.94926459 | AE25: =(Untransformed!AE86) -> 1.3377201 | AF25: =(Untransformed!AF86) -> 3.0307248 | AG25: =(Untransformed!AG86) -> 10804.056 | AH25: =LOG10(AG25) -> 4.0335868
A26: =(Untransformed!A82) -> 0.66419438 | B26: =(Untransformed!B82) -> 1.2567213 | C26: 1 | D26: =(Untransformed!D82) -> 0.90194986 | E26: =(Untransformed!E82) -> 0.84581538 | F26: =(Untransformed!F82) -> 0.7767185 | G26: =(Untransformed!G82) -> 1.0700111 | H26: =(Untransformed!H82) -> 0.84812952 | I26: =(Untransformed!I82) -> 1.4687262 | J26: =(Untransformed!J82) -> 1.9387914 | K26: 1 | L26: =(Untransformed!L82) -> 0.69554684 | M26: =(Untransformed!M82) -> 1.0384404 | N26: =(Untransformed!N82) -> 0.38832374 | O26: =(Untransformed!O82) -> 0.78101017 | P26: =(Untransformed!P82) -> 0.40777436 | Q26: =(Untransformed!Q82) -> 0.18853166 | R26: =(Untransformed!R82) -> 0.30342309 | S26: 1 | T26: =(Untransformed!T82) -> 1.2877515 | U26: =(Untransformed!U82) -> 1.8079691 | V26: =(Untransformed!V82) -> 2.2565339 | W26: =(Untransformed!W82) -> 2.5047888 | X26: =(Untransformed!X82) -> 2.4108545 | Y26: =(Untransformed!Y82) -> 4.6251746 | Z26: =(Untransformed!Z82) -> 1.5489418 | AA26: 1 | AB26: =(Untransformed!AB82) -> 1.2168461 | AC26: =(Untransformed!AC82) -> 0.1425176 | AD26: =(Untransformed!AD82) -> 0.96956541 | AE26: =(Untransformed!AE82) -> 1.2947107 | AF26: =(Untransformed!AF82) -> 3.0197203 | AG26: =(Untransformed!AG82) -> 10805.404 | AH26: =LOG10(AG26) -> 4.033641
A27: =(Untransformed!A90) -> 0.66419438 | B27: =(Untransformed!B90) -> 1.2567213 | C27: 1 | D27: =(Untransformed!D90) -> 0.90194986 | E27: =(Untransformed!E90) -> 0.84581538 | F27: =(Untransformed!F90) -> 0.7767185 | G27: =(Untransformed!G90) -> 1.0700111 | H27: =(Untransformed!H90) -> 0.84812952 | I27: =(Untransformed!I90) -> 1.4687262 | J27: =(Untransformed!J90) -> 1.9387914 | K27: 1 | L27: =(Untransformed!L90) -> 0.69554684 | M27: =(Untransformed!M90) -> 1.0384404 | N27: =(Untransformed!N90) -> 0.38832374 | O27: =(Untransformed!O90) -> 0.78101017 | P27: =(Untransformed!P90) -> 0.40777436 | Q27: =(Untransformed!Q90) -> 0.17929159 | R27: =(Untransformed!R90) -> 0.28250444 | S27: 1 | T27: =(Untransformed!T90) -> 1.2942842 | U27: =(Untransformed!U90) -> 1.878435 | V27: =(Untransformed!V90) -> 2.3022398 | W27: =(Untransformed!W90) -> 2.4848832 | X27: =(Untransformed!X90) -> 2.4518859 | Y27: =(Untransformed!Y90) -> 5.2597242 | Z27: =(Untransformed!Z90) -> 1.9309065 | AA27: 1 | AB27: =(Untransformed!AB90) -> 1.2846115 | AC27: =(Untransformed!AC90) -> 1.595333e-08 | AD27: =(Untransformed!AD90) -> 0.94363543 | AE27: =(Untransformed!AE90) -> 1.386822 | AF27: =(Untransformed!AF90) -> 2.923483 | AG27: =(Untransformed!AG90) -> 10824.024 | AH27: =LOG10(AG27) -> 4.0343887
A28: =(Untransformed!A91) -> 0.66419438 | B28: =(Untransformed!B91) -> 1.2567213 | C28: 1 | D28: =(Untransformed!D91) -> 0.90194986 | E28: =(Untransformed!E91) -> 0.84581538 | F28: =(Untransformed!F91) -> 0.7767185 | G28: =(Untransformed!G91) -> 1.0700111 | H28: =(Untransformed!H91) -> 0.84812952 | I28: =(Untransformed!I91) -> 1.4687262 | J28: =(Untransformed!J91) -> 1.9387914 | K28: 1 | L28: =(Untransformed!L91) -> 0.69554684 | M28: =(Untransformed!M91) -> 1.0384404 | N28: =(Untransformed!N91) -> 0.38832374 | O28: =(Untransformed!O91) -> 0.78101017 | P28: =(Untransformed!P91) -> 0.40777436 | Q28: =(Untransformed!Q91) -> 0.18711974 | R28: =(Untransformed!R91) -> 0.38951636 | S28: 1 | T28: =(Untransformed!T91) -> 1.2847749 | U28: =(Untransformed!U91) -> 1.8845572 | V28: =(Untransformed!V91) -> 2.3042661 | W28: =(Untransformed!W91) -> 2.5008243 | X28: =(Untransformed!X91) -> 2.4848926 | Y28: =(Untransformed!Y91) -> 4.4500644 | Z28: =(Untransformed!Z91) -> 0.4318823 | AA28: 1 | AB28: =(Untransformed!AB91) -> 1.1803217 | AC28: =(Untransformed!AC91) -> 0.072023001 | AD28: =(Untransformed!AD91) -> 0.82188646 | AE28: =(Untransformed!AE91) -> 1.2450327 | AF28: =(Untransformed!AF91) -> 2.6182821 | AG28: =(Untransformed!AG91) -> 10856.616 | AH28: =LOG10(AG28) -> 4.0356945
A29: =(Untransformed!A88) -> 0.66419438 | B29: =(Untransformed!B88) -> 1.2567213 | C29: 1 | D29: =(Untransformed!D88) -> 0.90194986 | E29: =(Untransformed!E88) -> 0.84581538 | F29: =(Untransformed!F88) -> 0.7767185 | G29: =(Untransformed!G88) -> 1.0700111 | H29: =(Untransformed!H88) -> 0.84812952 | I29: =(Untransformed!I88) -> 1.4687262 | J29: =(Untransformed!J88) -> 1.9387914 | K29: 1 | L29: =(Untransformed!L88) -> 0.69554684 | M29: =(Untransformed!M88) -> 1.0384404 | N29: =(Untransformed!N88) -> 0.38832374 | O29: =(Untransformed!O88) -> 0.78101017 | P29: =(Untransformed!P88) -> 0.40777436 | Q29: =(Untransformed!Q88) -> 0.27783147 | R29: =(Untransformed!R88) -> 0.51210381 | S29: 1 | T29: =(Untransformed!T88) -> 1.4163534 | U29: =(Untransformed!U88) -> 2.0000773 | V29: =(Untransformed!V88) -> 2.2713852 | W29: =(Untransformed!W88) -> 2.7896602 | X29: =(Untransformed!X88) -> 2.8299591 | Y29: =(Untransformed!Y88) -> 0.13886132 | Z29: =(Untransformed!Z88) -> 0.08233797 | AA29: 1 | AB29: =(Untransformed!AB88) -> 0.93560842 | AC29: =(Untransformed!AC88) -> 0.0079083493 | AD29: =(Untransformed!AD88) -> 1.0461891 | AE29: =(Untransformed!AE88) -> 0.74377857 | AF29: =(Untransformed!AF88) -> 2.0305345 | AG29: =(Untransformed!AG88) -> 11276.891 | AH29: =LOG10(AG29) -> 4.0521894
A30: =(Untransformed!A85) -> 0.66419438 | B30: =(Untransformed!B85) -> 1.2567213 | C30: 1 | D30: =(Untransformed!D85) -> 0.90194986 | E30: =(Untransformed!E85) -> 0.84581538 | F30: =(Untransformed!F85) -> 0.7767185 | G30: =(Untransformed!G85) -> 1.0700111 | H30: =(Untransformed!H85) -> 0.84812952 | I30: =(Untransformed!I85) -> 1.4687262 | J30: =(Untransformed!J85) -> 1.9387914 | K30: 1 | L30: =(Untransformed!L85) -> 0.69554684 | M30: =(Untransformed!M85) -> 1.0384404 | N30: =(Untransformed!N85) -> 0.38832374 | O30: =(Untransformed!O85) -> 0.78101017 | P30: =(Untransformed!P85) -> 0.40777436 | Q30: =(Untransformed!Q85) -> 0.13555763 | R30: =(Untransformed!R85) -> 0.51165372 | S30: 1 | T30: =(Untransformed!T85) -> 1.4253961 | U30: =(Untransformed!U85) -> 2.1612534 | V30: =(Untransformed!V85) -> 2.8224733 | W30: =(Untransformed!W85) -> 3.1226944 | X30: =(Untransformed!X85) -> 3.2053543 | Y30: =(Untransformed!Y85) -> 9.5320529e-08 | Z30: =(Untransformed!Z85) -> 0.00029295697 | AA30: 1 | AB30: =(Untransformed!AB85) -> 0.82931839 | AC30: =(Untransformed!AC85) -> 0.00010177596 | AD30: =(Untransformed!AD85) -> 0.05155567 | AE30: =(Untransformed!AE85) -> 0.78448538 | AF30: =(Untransformed!AF85) -> 1.2254658 | AG30: =(Untransformed!AG85) -> 12931.297 | AH30: =LOG10(AG30) -> 4.1116421
A31: =(Untransformed!A83) -> 0.66419438 | B31: =(Untransformed!B83) -> 1.2567213 | C31: 1 | D31: =(Untransformed!D83) -> 0.90194986 | E31: =(Untransformed!E83) -> 0.84581538 | F31: =(Untransformed!F83) -> 0.7767185 | G31: =(Untransformed!G83) -> 1.0700111 | H31: =(Untransformed!H83) -> 0.84812952 | I31: =(Untransformed!I83) -> 1.4687262 | J31: =(Untransformed!J83) -> 1.9387914 | K31: 1 | L31: =(Untransformed!L83) -> 0.69554684 | M31: =(Untransformed!M83) -> 1.0384404 | N31: =(Untransformed!N83) -> 0.38832374 | O31: =(Untransformed!O83) -> 0.78101017 | P31: =(Untransformed!P83) -> 0.40777436 | Q31: =(Untransformed!Q83) -> 0.062270465 | R31: =(Untransformed!R83) -> 0.17825135 | S31: 1 | T31: =(Untransformed!T83) -> 0.66684197 | U31: =(Untransformed!U83) -> 0.61546163 | V31: =(Untransformed!V83) -> 1.2858034 | W31: =(Untransformed!W83) -> 2.2591813 | X31: =(Untransformed!X83) -> 2.4619485 | Y31: =(Untransformed!Y83) -> 1.7584401e-06 | Z31: =(Untransformed!Z83) -> 0.00059933178 | AA31: 1 | AB31: =(Untransformed!AB83) -> 3.925428e-05 | AC31: =(Untransformed!AC83) -> 7.0447159 | AD31: =(Untransformed!AD83) -> 0.012089939 | AE31: =(Untransformed!AE83) -> 0.73237737 | AF31: =(Untransformed!AF83) -> 8.2600525e-08 | AG31: =(Untransformed!AG83) -> 30114.474 | AH31: =LOG10(AG31) -> 4.4787753
A32: =(Untransformed!A81) -> 0.76328083 | B32: =(Untransformed!B81) -> 1.1382361 | C32: 1 | D32: =(Untransformed!D81) -> 0.9604268 | E32: =(Untransformed!E81) -> 0.25843117 | F32: =(Untransformed!F81) -> 1.0048173 | G32: =(Untransformed!G81) -> 1.3186868 | H32: =(Untransformed!H81) -> 1.4919181 | I32: =(Untransformed!I81) -> 1.1019997 | J32: =(Untransformed!J81) -> 0.2653217 | K32: 1 | L32: =(Untransformed!L81) -> 1.0974451 | M32: =(Untransformed!M81) -> 0.35108309 | N32: =(Untransformed!N81) -> 1.5377837 | O32: =(Untransformed!O81) -> 0.2848732 | P32: =(Untransformed!P81) -> 0.3127071 | Q32: =(Untransformed!Q81) -> 0.18245693 | R32: =(Untransformed!R81) -> 0.29650575 | S32: 1 | T32: =(Untransformed!T81) -> 1.2790012 | U32: =(Untransformed!U81) -> 1.809227 | V32: =(Untransformed!V81) -> 2.2381462 | W32: =(Untransformed!W81) -> 2.4652123 | X32: =(Untransformed!X81) -> 2.3933026 | Y32: =(Untransformed!Y81) -> 5.0706082 | Z32: =(Untransformed!Z81) -> 1.6631449 | AA32: 1 | AB32: =(Untransformed!AB81) -> 1.2597695 | AC32: =(Untransformed!AC81) -> 0.1088654 | AD32: =(Untransformed!AD81) -> 1.0168233 | AE32: =(Untransformed!AE81) -> 1.3620178 | AF32: =(Untransformed!AF81) -> 3.0799336 | AG32: =(Untransformed!AG81) -> 10802.288 | AH32: =LOG10(AG32) -> 4.0335158 | AI32: 1
A33: =(Untransformed!A74) -> 0.76328083 | B33: =(Untransformed!B74) -> 1.1382361 | C33: 1 | D33: =(Untransformed!D74) -> 0.9604268 | E33: =(Untransformed!E74) -> 0.25843117 | F33: =(Untransformed!F74) -> 1.0048173 | G33: =(Untransformed!G74) -> 1.3186868 | H33: =(Untransformed!H74) -> 1.4919181 | I33: =(Untransformed!I74) -> 1.1019997 | J33: =(Untransformed!J74) -> 0.2653217 | K33: 1 | L33: =(Untransformed!L74) -> 1.0974451 | M33: =(Untransformed!M74) -> 0.35108309 | N33: =(Untransformed!N74) -> 1.5377837 | O33: =(Untransformed!O74) -> 0.2848732 | P33: =(Untransformed!P74) -> 0.3127071 | Q33: =(Untransformed!Q74) -> 0.18549157 | R33: =(Untransformed!R74) -> 0.30109127 | S33: 1 | T33: =(Untransformed!T74) -> 1.279976 | U33: =(Untransformed!U74) -> 1.8097726 | V33: =(Untransformed!V74) -> 2.2356764 | W33: =(Untransformed!W74) -> 2.4663796 | X33: =(Untransformed!X74) -> 2.3966019 | Y33: =(Untransformed!Y74) -> 4.8773606 | Z33: =(Untransformed!Z74) -> 1.6021418 | AA33: 1 | AB33: =(Untransformed!AB74) -> 1.2621994 | AC33: =(Untransformed!AC74) -> 0.1106436 | AD33: =(Untransformed!AD74) -> 1.0273056 | AE33: =(Untransformed!AE74) -> 1.3575077 | AF33: =(Untransformed!AF74) -> 3.0750099 | AG33: =(Untransformed!AG74) -> 10802.563 | AH33: =LOG10(AG33) -> 4.0335268
A34: =(Untransformed!A75) -> 0.76328083 | B34: =(Untransformed!B75) -> 1.1382361 | C34: 1 | D34: =(Untransformed!D75) -> 0.9604268 | E34: =(Untransformed!E75) -> 0.25843117 | F34: =(Untransformed!F75) -> 1.0048173 | G34: =(Untransformed!G75) -> 1.3186868 | H34: =(Untransformed!H75) -> 1.4919181 | I34: =(Untransformed!I75) -> 1.1019997 | J34: =(Untransformed!J75) -> 0.2653217 | K34: 1 | L34: =(Untransformed!L75) -> 1.0974451 | M34: =(Untransformed!M75) -> 0.35108309 | N34: =(Untransformed!N75) -> 1.5377837 | O34: =(Untransformed!O75) -> 0.2848732 | P34: =(Untransformed!P75) -> 0.3127071 | Q34: =(Untransformed!Q75) -> 0.18476594 | R34: =(Untransformed!R75) -> 0.30421603 | S34: 1 | T34: =(Untransformed!T75) -> 1.277018 | U34: =(Untransformed!U75) -> 1.8161515 | V34: =(Untransformed!V75) -> 2.2487416 | W34: =(Untransformed!W75) -> 2.4673143 | X34: =(Untransformed!X75) -> 2.3981148 | Y34: =(Untransformed!Y75) -> 4.8846929 | Z34: =(Untransformed!Z75) -> 1.524723 | AA34: 1 | AB34: =(Untransformed!AB75) -> 1.2551827 | AC34: =(Untransformed!AC75) -> 0.11125877 | AD34: =(Untransformed!AD75) -> 0.98198715 | AE34: =(Untransformed!AE75) -> 1.3596097 | AF34: =(Untransformed!AF75) -> 3.0361504 | AG34: =(Untransformed!AG75) -> 10802.848 | AH34: =LOG10(AG34) -> 4.0335383
A35: =(Untransformed!A77) -> 0.76328083 | B35: =(Untransformed!B77) -> 1.1382361 | C35: 1 | D35: =(Untransformed!D77) -> 0.9604268 | E35: =(Untransformed!E77) -> 0.25843117 | F35: =(Untransformed!F77) -> 1.0048173 | G35: =(Untransformed!G77) -> 1.3186868 | H35: =(Untransformed!H77) -> 1.4919181 | I35: =(Untransformed!I77) -> 1.1019997 | J35: =(Untransformed!J77) -> 0.2653217 | K35: 1 | L35: =(Untransformed!L77) -> 1.0974451 | M35: =(Untransformed!M77) -> 0.35108309 | N35: =(Untransformed!N77) -> 1.5377837 | O35: =(Untransformed!O77) -> 0.2848732 | P35: =(Untransformed!P77) -> 0.3127071 | Q35: =(Untransformed!Q77) -> 0.18426082 | R35: =(Untransformed!R77) -> 0.31409235 | S35: 1 | T35: =(Untransformed!T77) -> 1.2832381 | U35: =(Untransformed!U77) -> 1.8214972 | V35: =(Untransformed!V77) -> 2.2786524 | W35: =(Untransformed!W77) -> 2.4951285 | X35: =(Untransformed!X77) -> 2.4098719 | Y35: =(Untransformed!Y77) -> 4.8006701 | Z35: =(Untransformed!Z77) -> 1.3398835 | AA35: 1 | AB35: =(Untransformed!AB77) -> 1.2143879 | AC35: =(Untransformed!AC77) -> 0.13073976 | AD35: =(Untransformed!AD77) -> 0.90160965 | AE35: =(Untransformed!AE77) -> 1.3069046 | AF35: =(Untransformed!AF77) -> 2.9561279 | AG35: =(Untransformed!AG77) -> 10806.031 | AH35: =LOG10(AG35) -> 4.0336662
A36: =(Untransformed!A79) -> 0.76328083 | B36: =(Untransformed!B79) -> 1.1382361 | C36: 1 | D36: =(Untransformed!D79) -> 0.9604268 | E36: =(Untransformed!E79) -> 0.25843117 | F36: =(Untransformed!F79) -> 1.0048173 | G36: =(Untransformed!G79) -> 1.3186868 | H36: =(Untransformed!H79) -> 1.4919181 | I36: =(Untransformed!I79) -> 1.1019997 | J36: =(Untransformed!J79) -> 0.2653217 | K36: 1 | L36: =(Untransformed!L79) -> 1.0974451 | M36: =(Untransformed!M79) -> 0.35108309 | N36: =(Untransformed!N79) -> 1.5377837 | O36: =(Untransformed!O79) -> 0.2848732 | P36: =(Untransformed!P79) -> 0.3127071 | Q36: =(Untransformed!Q79) -> 0.18572163 | R36: =(Untransformed!R79) -> 0.31975566 | S36: 1 | T36: =(Untransformed!T79) -> 1.2982419 | U36: =(Untransformed!U79) -> 1.8878727 | V36: =(Untransformed!V79) -> 2.3010372 | W36: =(Untransformed!W79) -> 2.5195646 | X36: =(Untransformed!X79) -> 2.4923034 | Y36: =(Untransformed!Y79) -> 4.6817143 | Z36: =(Untransformed!Z79) -> 1.2864429 | AA36: 1 | AB36: =(Untransformed!AB79) -> 1.2070402 | AC36: =(Untransformed!AC79) -> 0.022614798 | AD36: =(Untransformed!AD79) -> 0.90998804 | AE36: =(Untransformed!AE79) -> 1.25638 | AF36: =(Untransformed!AF79) -> 2.7289986 | AG36: =(Untransformed!AG79) -> 10813.897 | AH36: =LOG10(AG36) -> 4.0339822
A37: =(Untransformed!A76) -> 0.76328083 | B37: =(Untransformed!B76) -> 1.1382361 | C37: 1 | D37: =(Untransformed!D76) -> 0.9604268 | E37: =(Untransformed!E76) -> 0.25843117 | F37: =(Untransformed!F76) -> 1.0048173 | G37: =(Untransformed!G76) -> 1.3186868 | H37: =(Untransformed!H76) -> 1.4919181 | I37: =(Untransformed!I76) -> 1.1019997 | J37: =(Untransformed!J76) -> 0.2653217 | K37: 1 | L37: =(Untransformed!L76) -> 1.0974451 | M37: =(Untransformed!M76) -> 0.35108309 | N37: =(Untransformed!N76) -> 1.5377837 | O37: =(Untransformed!O76) -> 0.2848732 | P37: =(Untransformed!P76) -> 0.3127071 | Q37: =(Untransformed!Q76) -> 0.1900185 | R37: =(Untransformed!R76) -> 0.32504808 | S37: 1 | T37: =(Untransformed!T76) -> 1.3252136 | U37: =(Untransformed!U76) -> 1.9028619 | V37: =(Untransformed!V76) -> 2.2781298 | W37: =(Untransformed!W76) -> 2.5860307 | X37: =(Untransformed!X76) -> 2.5659773 | Y37: =(Untransformed!Y76) -> 4.5338577 | Z37: =(Untransformed!Z76) -> 1.2489394 | AA37: 1 | AB37: =(Untransformed!AB76) -> 1.121745 | AC37: =(Untransformed!AC76) -> 0.010314397 | AD37: =(Untransformed!AD76) -> 1.0116561 | AE37: =(Untransformed!AE76) -> 1.1014495 | AF37: =(Untransformed!AF76) -> 2.6080201 | AG37: =(Untransformed!AG76) -> 10819.57 | AH37: =LOG10(AG37) -> 4.03421
A38: =(Untransformed!A78) -> 0.76328083 | B38: =(Untransformed!B78) -> 1.1382361 | C38: 1 | D38: =(Untransformed!D78) -> 0.9604268 | E38: =(Untransformed!E78) -> 0.25843117 | F38: =(Untransformed!F78) -> 1.0048173 | G38: =(Untransformed!G78) -> 1.3186868 | H38: =(Untransformed!H78) -> 1.4919181 | I38: =(Untransformed!I78) -> 1.1019997 | J38: =(Untransformed!J78) -> 0.2653217 | K38: 1 | L38: =(Untransformed!L78) -> 1.0974451 | M38: =(Untransformed!M78) -> 0.35108309 | N38: =(Untransformed!N78) -> 1.5377837 | O38: =(Untransformed!O78) -> 0.2848732 | P38: =(Untransformed!P78) -> 0.3127071 | Q38: =(Untransformed!Q78) -> 0.17776715 | R38: =(Untransformed!R78) -> 0.26763095 | S38: 1 | T38: =(Untransformed!T78) -> 1.244415 | U38: =(Untransformed!U78) -> 1.78663 | V38: =(Untransformed!V78) -> 2.1939138 | W38: =(Untransformed!W78) -> 2.3556998 | X38: =(Untransformed!X78) -> 2.2919063 | Y38: =(Untransformed!Y78) -> 5.6731767 | Z38: =(Untransformed!Z78) -> 2.4008637 | AA38: 1 | AB38: =(Untransformed!AB78) -> 1.5070464 | AC38: =(Untransformed!AC78) -> 0.043802882 | AD38: =(Untransformed!AD78) -> 1.1599579 | AE38: =(Untransformed!AE78) -> 1.6574754 | AF38: =(Untransformed!AF78) -> 3.5644494 | AG38: =(Untransformed!AG78) -> 10820.709 | AH38: =LOG10(AG38) -> 4.0342557
A39: =(Untransformed!A72) -> 0.76328083 | B39: =(Untransformed!B72) -> 1.1382361 | C39: 1 | D39: =(Untransformed!D72) -> 0.9604268 | E39: =(Untransformed!E72) -> 0.25843117 | F39: =(Untransformed!F72) -> 1.0048173 | G39: =(Untransformed!G72) -> 1.3186868 | H39: =(Untransformed!H72) -> 1.4919181 | I39: =(Untransformed!I72) -> 1.1019997 | J39: =(Untransformed!J72) -> 0.2653217 | K39: 1 | L39: =(Untransformed!L72) -> 1.0974451 | M39: =(Untransformed!M72) -> 0.35108309 | N39: =(Untransformed!N72) -> 1.5377837 | O39: =(Untransformed!O72) -> 0.2848732 | P39: =(Untransformed!P72) -> 0.3127071 | Q39: =(Untransformed!Q72) -> 0.20354858 | R39: =(Untransformed!R72) -> 0.36409566 | S39: 1 | T39: =(Untransformed!T72) -> 1.3572721 | U39: =(Untransformed!U72) -> 1.9515501 | V39: =(Untransformed!V72) -> 2.4294476 | W39: =(Untransformed!W72) -> 2.6772582 | X39: =(Untransformed!X72) -> 2.650536 | Y39: =(Untransformed!Y72) -> 3.4272058 | Z39: =(Untransformed!Z72) -> 0.76689907 | AA39: 1 | AB39: =(Untransformed!AB72) -> 1.0184134 | AC39: =(Untransformed!AC72) -> 0.070641355 | AD39: =(Untransformed!AD72) -> 0.68814917 | AE39: =(Untransformed!AE72) -> 1.0609876 | AF39: =(Untransformed!AF72) -> 2.2752479 | AG39: =(Untransformed!AG72) -> 10851.744 | AH39: =LOG10(AG39) -> 4.0354996
A40: =(Untransformed!A73) -> 0.76328083 | B40: =(Untransformed!B73) -> 1.1382361 | C40: 1 | D40: =(Untransformed!D73) -> 0.9604268 | E40: =(Untransformed!E73) -> 0.25843117 | F40: =(Untransformed!F73) -> 1.0048173 | G40: =(Untransformed!G73) -> 1.3186868 | H40: =(Untransformed!H73) -> 1.4919181 | I40: =(Untransformed!I73) -> 1.1019997 | J40: =(Untransformed!J73) -> 0.2653217 | K40: 1 | L40: =(Untransformed!L73) -> 1.0974451 | M40: =(Untransformed!M73) -> 0.35108309 | N40: =(Untransformed!N73) -> 1.5377837 | O40: =(Untransformed!O73) -> 0.2848732 | P40: =(Untransformed!P73) -> 0.3127071 | Q40: =(Untransformed!Q73) -> 0.21075583 | R40: =(Untransformed!R73) -> 0.43433109 | S40: 1 | T40: =(Untransformed!T73) -> 1.6000667 | U40: =(Untransformed!U73) -> 2.1178989 | V40: =(Untransformed!V73) -> 2.4319707 | W40: =(Untransformed!W73) -> 3.0828547 | X40: =(Untransformed!X73) -> 3.1305892 | Y40: =(Untransformed!Y73) -> 3.4265101 | Z40: =(Untransformed!Z73) -> 0.20001738 | AA40: 1 | AB40: =(Untransformed!AB73) -> 0.46166093 | AC40: =(Untransformed!AC73) -> 0.030790838 | AD40: =(Untransformed!AD73) -> 0.81661884 | AE40: =(Untransformed!AE73) -> 0.53751161 | AF40: =(Untransformed!AF73) -> 1.4744172 | AG40: =(Untransformed!AG73) -> 11211.12 | AH40: =LOG10(AG40) -> 4.049649
...

Sheet Best of each group
A1: s0-9i | B1: s10-19i | C1: s20-29i | D1: s30-39i | E1: s40-49i | F1: s50-59i | G1: s60-69i | H1: s70-79i | I1: v0-9i | J1: v10-19i | K1: s20-29i | L1: v30-39i | M1: v40-49i | N1: v50-59i | O1: v60-69i | P1: v70-79i | Q1: s0-9 | R1: s10-19 | S1: s20-29 | T1: s30-39 | U1: s40-49 | V1: s50-59 | W1: s60-69 | X1: s70-79 | Y1: v0-9 | Z1: v10-19 | AA1: s20-29 | AB1: v30-39 | AC1: v40-49 | AD1: v50-59 | AE1: v60-69 | AF1: v70-79 | AG1: kl_div | AH1: Log10(kl) | AI1: Best
A2: {=_xlfn._xlws.FILTER('All trials'!A:AI, 'All trials'!AI:AI = 1,'All trials'!AI2310)} -> 0.19103755 | B2: 0.60596125 | C2: 1 | D2: 0.93763624 | E2: 0.70977082 | F2: 1.6797631 | G2: 0.87223289 | H2: 0.72932341 | I2: 1.524351 | J2: 0.81706952 | K2: 1 | L2: 0.55631967 | M2: 1.1017943 | N2: 0.49346278 | O2: 0.52694774 | P2: 0.73431475 | Q2: 0.18273963 | R2: 0.29642921 | S2: 1 | T2: 1.2744013 | U2: 1.8055268 | V2: 2.2343444 | W2: 2.4558851 | X2: 2.383999 | Y2: 5.0750012 | Z2: 1.6756666 | AA2: 1 | AB2: 1.2814424 | AC2: 0.10832239 | AD2: 1.0261647 | AE2: 1.3823864 | AF2: 3.1185226 | AG2: 10802.205 | AH2: 4.0335124 | AI2: 1
A3: 0.66171329 | B3: 1.4989558 | C3: 1 | D3: 0.2846583 | E3: 0.94904862 | F3: 0.40859493 | G3: 1.2419868 | H3: 0.85690348 | I3: 0.76364275 | J3: 0.6449456 | K3: 1 | L3: 0.97693163 | M3: 0.9428961 | N3: 1.3976706 | O3: 0.88298659 | P3: 1.1975141 | Q3: 0.18249529 | R3: 0.29774209 | S3: 1 | T3: 1.2755465 | U3: 1.8050698 | V3: 2.2364647 | W3: 2.4625077 | X3: 2.3853596 | Y3: 5.0976164 | Z3: 1.6455982 | AA3: 1 | AB3: 1.2689086 | AC3: 0.11454424 | AD3: 1.0177027 | AE3: 1.3676879 | AF3: 3.1078517 | AG3: 10802.267 | AH3: 4.0335149 | AI3: 1
A4: 0.66419438 | B4: 1.2567213 | C4: 1 | D4: 0.90194986 | E4: 0.84581538 | F4: 0.7767185 | G4: 1.0700111 | H4: 0.84812952 | I4: 1.4687262 | J4: 1.9387914 | K4: 1 | L4: 0.69554684 | M4: 1.0384404 | N4: 0.38832374 | O4: 0.78101017 | P4: 0.40777436 | Q4: 0.18353991 | R4: 0.30039464 | S4: 1 | T4: 1.2734232 | U4: 1.8096814 | V4: 2.226145 | W4: 2.4505811 | X4: 2.3821806 | Y4: 5.0827644 | Z4: 1.6054632 | AA4: 1 | AB4: 1.2753206 | AC4: 0.10043799 | AD4: 1.0436962 | AE4: 1.3714431 | AF4: 3.107769 | AG4: 10802.638 | AH4: 4.0335298 | AI4: 1
